<mujoco model="ant_5leg">
  <compiler angle="degree" coordinate="local" inertiafromgeom="true"/>
  <option integrator="RK4" timestep="0.01"/>
  <custom>
    <!-- <numeric data="0.0 0.0 0.55 1.0 0.0 0.0 0.0 0.0 1.0 0.0 -1.0 0.0 -1.0 0.0 1.0" name="init_qpos"/> -->
    <numeric data="0.0 0.0 0.55 1.0 0.0 0.0 0.0 0.0 1.0 0.0 -1.0 0.0 1.0 0.0 -1.0 0.0 1.0" name="init_qpos"/>
  </custom>
  <default>
    <joint armature="1" damping="1" limited=  "true"/>
    <geom conaffinity="0" condim="3" density="5.0" friction="1 0.5 0.5" margin="0.01" rgba="0.8 0.6 0.4 1"/>
  </default>
  <asset>
    <texture builtin="gradient" height="100" rgb1="1 1 1" rgb2="0 0 0" type="skybox" width="100"/>
    <texture builtin="flat" height="1278" mark="cross" markrgb="1 1 1" name="texgeom" random="0.01" rgb1="0.8 0.6 0.4" rgb2="0.8 0.6 0.4" type="cube" width="127"/>
    <texture builtin="checker" height="100" name="texplane" rgb1="0 0 0" rgb2="0.8 0.8 0.8" type="2d" width="100"/>
    <material name="MatPlane" reflectance="0.5" shininess="1" specular="1" texrepeat="60 60" texture="texplane"/>
    <material name="geom" texture="texgeom" texuniform="true"/>
  </asset>
  <worldbody>
    <light cutoff="100" diffuse="1 1 1" dir="-0 0 -1.3" directional="true" exponent="1" pos="0 0 1.3" specular=".1 .1 .1"/>
    <geom conaffinity="1" condim="3" material="MatPlane" name="floor" pos="0 0 0" rgba="0.8 0.9 0.8 1" size="40 40 40" type="plane"/>
    <body name="torso" pos="0 0 0.75">
      <camera name="track" mode="trackcom" pos="0 -3 0.3" xyaxes="1 0 0 0 0 1"/>
      <geom name="torso_geom" pos="0 0 0" size="0.25" type="sphere"/>
      <joint armature="0" damping="0" limited="false" margin="0.01" name="root" pos="0 0 0" type="free"/>
      <!-- leg_0 :   0 deg -->
      <body name="leg_0" pos="0 0 0">
        <geom fromto="0.0 0.0 0.0 0.2828427125 0 0" name="aux_0_geom" size="0.08" type="capsule"/>
        <body name="aux_0" pos="0.2828427125 0 0" >
          <!-- <joint name="hip_0" type="hinge" axis="0 0 1" pos="0 0 0" range="-30 30"/> -->
          <joint name="hip_0" type="hinge" axis="0 0 1" pos="0 0 0" range="-30 30"/>
          <geom fromto="0 0 0   0.2828427125 0 0" name="leg0_geom" size="0.08" type="capsule" />
          <body pos="0.2828427125 0 0">
            <joint name="ankle_0" type="hinge" axis="0 1 0" pos="0 0 0" range="30 70"/>
            <!-- Forest Green -->
            <geom fromto="0 0 0   0.565685425 0 0" name="leg0_ankle_geom" size="0.08" type="capsule"  rgba="0.13 0.55 0.13 1" /> 
          </body>                 
        </body>
      </body>

      <!-- leg_1 :  72 deg -->
      <body name="leg_1" pos="0 0 0">
        <geom fromto="0 0 0   0.0874032049 0.2689994048 0" name="aux_1_geom" size="0.08" type="capsule"/>
        <body name="aux_1" pos="0.0874032049 0.2689994048 0">
          <!-- <joint name="hip_1" type="hinge" axis="0 0 1" pos="0 0 0" range="-30 30"/> -->
          <joint name="hip_1" type="hinge" axis="0 0 1" pos="0 0 0" range="-30 30"/>
          <geom fromto="0 0 0   0.0874032049 0.2689994048 0" name="leg1_geom" size="0.08" type="capsule"/>
          <body pos="0.0874032049 0.2689994048 0">
            <joint name="ankle_1" type="hinge" axis="-0.95105651629 0.30901699437 0" pos="0 0 0" range="30 70"/>
            <!-- Sky Blue -->
            <geom fromto="0 0 0   0.1748064098 0.5379988096 0" name="leg1_ankle_geom" size="0.08" type="capsule" rgba="0.53 0.81 0.98 1" />
          </body>
        </body>
      </body>

      <!-- leg_2 : 144 deg -->
      <body name="leg_2" pos="0 0 0">
        <geom fromto="0 0 0   -0.2288245611 0.1662507751 0" name="aux_2_geom" size="0.08" type="capsule"/>
        <body name="aux_2" pos="-0.2288245611 0.1662507751 0">
          <!-- <joint name="hip_2" type="hinge" axis="0 0 1" pos="0 0 0" range="-30 30"/> -->
          <joint name="hip_2" type="hinge" axis="0 0 1" pos="0 0 0" range="-30 30"/>
          <geom fromto="0 0 0   -0.2288245611 0.1662507751 0" name="leg2_geom" size="0.08" type="capsule"/>
          <body pos="-0.2288245611 0.1662507751 0">
            <!-- <joint name="ankle_2" type="hinge" axis="-0.58778525229 -0.80901699437 0" pos="0 0 0" range="30 70"/> -->
            <joint name="ankle_2" type="hinge" axis="0.58778525229 0.80901699437 0" pos="0 0 0" range="-70 -30"/>
            <!-- Sunset Orange -->
            <geom fromto="0 0 0   -0.4576491223 0.3325015503 0" name="leg2_ankle_geom" size="0.08" type="capsule" rgba="1.0 0.47 0.0 1"/>
          </body>
        </body>
      </body>

      <!-- leg_3 : 216 deg -->
      <body name="leg_3" pos="0 0 0">
        <geom fromto="0 0 0   -0.2288245611 -0.1662507751 0" name="aux_3_geom" size="0.08" type="capsule"/>
        <body name="aux_3" pos="-0.2288245611 -0.1662507751 0">
          <!-- <joint name="hip_3" type="hinge" axis="0 0 1" pos="0 0 0" range="-30 30"/> -->
          <joint name="hip_3" type="hinge" axis="0 0 1" pos="0 0 0" range="-30 30"/>
          <geom fromto="0 0 0   -0.2288245611 -0.1662507751 0" name="leg3_geom" size="0.08" type="capsule"/>
          <body pos="-0.2288245611 -0.1662507751 0">
            <joint name="ankle_3" type="hinge" axis="0.58778525229 -0.80901699437 0" pos="0 0 0" range="30 70"/>
            <!-- Royal Purple -->
            <geom fromto="0 0 0   -0.4576491223 -0.3325015503 0" name="leg3_ankle_geom" size="0.08" type="capsule" rgba="0.47 0.32 0.66 1"/>
          </body>
        </body>
      </body>

      <!-- leg_4 : 288 deg -->
      <body name="leg_4" pos="0 0 0">
        <geom fromto="0 0 0   0.0874032049 -0.2689994048 0" name="aux_4_geom" size="0.08" type="capsule"/>
        <body name="aux_4" pos="0.0874032049 -0.2689994048 0">
          <!-- <joint name="hip_4" type="hinge" axis="0 0 1" pos="0 0 0" range="-30 30"/> -->
          <joint name="hip_4" type="hinge" axis="0 0 1" pos="0 0 0" range="-30 30"/>
          <geom fromto="0 0 0   0.0874032049 -0.2689994048 0" name="leg4_geom" size="0.08" type="capsule"/>
          <body pos="0.0874032049 -0.2689994048 0">
            <!-- <joint name="ankle_4" type="hinge" axis="0.95105651629 0.30901699437 0" pos="0 0 0" range="30 70"/> -->
            <joint name="ankle_4" type="hinge" axis="-0.95105651629 -0.30901699437 0" pos="0 0 0" range="-70 -30"/>
            <!-- Slate Gray -->
            <geom fromto="0 0 0   0.1748064098 -0.5379988096 0" name="leg4_ankle_geom" size="0.08" type="capsule" rgba="0.44 0.5 0.56 1"/>
          </body>
        </body>
      </body>

    </body>
  </worldbody>

  <actuator>
    <motor joint="hip_0"   gear="150" ctrllimited="true" ctrlrange="-1 1"/>
    <motor joint="ankle_0" gear="150" ctrllimited="true" ctrlrange="-1 1"/>
    <motor joint="hip_1"   gear="150" ctrllimited="true" ctrlrange="-1 1"/>
    <motor joint="ankle_1" gear="150" ctrllimited="true" ctrlrange="-1 1"/>
    <motor joint="hip_2"   gear="150" ctrllimited="true" ctrlrange="-1 1"/>
    <motor joint="ankle_2" gear="150" ctrllimited="true" ctrlrange="-1 1"/>
    <motor joint="hip_3"   gear="150" ctrllimited="true" ctrlrange="-1 1"/>
    <motor joint="ankle_3" gear="150" ctrllimited="true" ctrlrange="-1 1"/>
    <motor joint="hip_4"   gear="150" ctrllimited="true" ctrlrange="-1 1"/>
    <motor joint="ankle_4" gear="150" ctrllimited="true" ctrlrange="-1 1"/>
  </actuator>
</mujoco>
